Workbook

Sheet 保険一覧
A1: 旭土地建物 保険契約一覧(令和8年6月10日現在)
A2: 出典: アップロードされた保険一覧ファイル「旭土地 2026.6.10」シート。青字=転記値、黒字=計算。保険料は月払=月額、年払=年額。返戻金は万円。
A4: 番号 | B4: 保険会社 | C4: 契約番号 | D4: 加入日 | E4: 契約者 | F4: 保険種類 | G4: 損金割合 | H4: 被保険者 | I4: 保険期間 | J4: 払込方法 | K4: 保険料(円) 月払=月額/年払=年額 | L4: 年間保険料(円) | M4: 年間損金計上額(円) | N4: 保険金 | O4: 返戻金(R8年・万円) | P4: 返戻率(R8年) | Q4: 意向 | R4: 年払の支払月 (加入日の月) | S4: 支払停止年月 (入力で反映) | T4: 備考
A5: 1 | B5: 大同生命 | C5: 679-166564-0 | D5: 44765 | E5: 旭土地 | F5: 全額損金 | G5: 0 | H5: 岡田 優子 | I5: 90歳まで | J5: 払済 | K5: 0 | L5: =IF(J5="月払",K5*12,IF(J5="年払",K5,0)) -> 0 | M5: =L5*G5 -> 0 | N5: 331万円 | O5: 165 | P5: 0.432 | Q5: 随時解約検討 | R5: =IF(J5="年払",MONTH(D5),"")
A6: 2 | B6: 大同生命 | C6: 697-166566-0 | D6: 44765 | E6: 旭土地 | F6: 全額損金 | G6: 0 | H6: 岡田 淳 | I6: 90歳まで | J6: 払済 | K6: 0 | L6: =IF(J6="月払",K6*12,IF(J6="年払",K6,0)) -> 0 | M6: =L6*G6 -> 0 | N6: 388万円 | O6: 266 | P6: 0.458 | Q6: 随時解約検討 | R6: =IF(J6="年払",MONTH(D6),"")
A7: 3 | B7: 大同生命 | C7: 636-016316-0 | D7: 44765 | E7: 旭土地 | F7: 全額損金 | G7: 0 | H7: Ｊ 岡田 優子 | I7: 90歳まで | J7: 払済 | K7: 0 | L7: =IF(J7="月払",K7*12,IF(J7="年払",K7,0)) -> 0 | M7: =L7*G7 -> 0 | N7: 638万円 | O7: 433 | P7: 0.528 | Q7: 2027年度払済？ | R7: =IF(J7="年払",MONTH(D7),"")
A8: 4 | B8: 大同生命 | C8: 656-028099-0 | D8: 44765 | E8: 旭土地 | F8: 全額損金 | G8: 0 | H8: Ｔ 岡田 優子 | I8: 90歳まで | J8: 払済 | K8: 0 | L8: =IF(J8="月払",K8*12,IF(J8="年払",K8,0)) -> 0 | M8: =L8*G8 -> 0 | N8: 622万円 | O8: 241 | P8: 0.449 | Q8: 2030年度払済？ | R8: =IF(J8="年払",MONTH(D8),"")
A9: 5 | B9: 大同生命 | C9: 086-376628-0 | D9: 44166 | E9: 旭土地 | F9: 全損 | G9: 1 | H9: 坂本 武 | I9: 終身 | J9: 月払 | K9: 22820 | L9: =IF(J9="月払",K9*12,IF(J9="年払",K9,0)) -> 273840 | M9: =L9*G9 -> 273840 | N9: 入院 10,000円 | Q9: 保有 | R9: =IF(J9="年払",MONTH(D9),"") | T9: 医療保険(入院日額1万円)。元表の損金計上合計に未算入
A10: 6 | B10: 大同生命 | C10: 636-010531-0 | D10: 44348 | E10: 旭土地 | F10: 全額損金 | G10: 1 | H10: 横山 清美 | I10: Ｊ 90歳まで | J10: 月払 | K10: 49130 | L10: =IF(J10="月払",K10*12,IF(J10="年払",K10,0)) -> 589560 | M10: =L10*G10 -> 589560 | N10: 1,500万円 | O10: 131 | P10: 0.4 | Q10: 保有 | R10: =IF(J10="年払",MONTH(D10),"")
A11: 7 | B11: 大同生命 | C11: 697-074568-0 | D11: 44166 | E11: 旭土地 | F11: 6割損金 | G11: 0.6 | H11: 坂本 武 | I11: 総Ｌ 100歳まで | J11: 月払 | K11: 505120 | L11: =IF(J11="月払",K11*12,IF(J11="年払",K11,0)) -> 6061440 | M11: =L11*G11 -> 3636864 | N11: 10,000万円 | O11: 2247 | P11: 0.688 | Q11: 2027年度払済？ | R11: =IF(J11="年払",MONTH(D11),"")
A12: 8 | B12: 大同生命 | C12: 697-129724-0 | D12: 44531 | E12: 旭土地 | F12: 6割損金 | G12: 0.6 | H12: 横山 清美 | I12: 90歳まで | J12: 月払 | K12: 57687 | L12: =IF(J12="月払",K12*12,IF(J12="年払",K12,0)) -> 692244 | M12: =L12*G12 -> 415346.4 | N12: 3,000万円 | O12: 196 | P12: 0.688 | Q12: 保有 | R12: =IF(J12="年払",MONTH(D12),"")
A13: 9 | B13: 大同生命 | C13: 636-013356-0 | D13: 44531 | E13: 旭土地 | F13: 6割損金 | G13: 0.6 | H13: 坂本 麻莉 | I13: Ｊ 90歳まで | J13: 月払 | K13: 179573 | L13: =IF(J13="月払",K13*12,IF(J13="年払",K13,0)) -> 2154876 | M13: =L13*G13 -> 1292925.6 | N13: 10,000万円 | O13: 654 | P13: 0.675 | Q13: 2027年度払済？ | R13: =IF(J13="年払",MONTH(D13),"")
A14: 10 | B14: 大同生命 | C14: 697-131400-0 | D14: 44531 | E14: 旭土地 | F14: 6割損金 | G14: 0.6 | H14: 坂本 麻莉 | I14: 総Ｌ 90歳まで | J14: 月払 | K14: 49628 | L14: =IF(J14="月払",K14*12,IF(J14="年払",K14,0)) -> 595536 | M14: =L14*G14 -> 357321.6 | N14: 6,000万円 | O14: 456 | P14: 0.646 | Q14: 保有 | R14: =IF(J14="年払",MONTH(D14),"")
A15: 11 | B15: 大同生命 | C15: 697-159957-0 | D15: 44733 | E15: 旭土地 | F15: 全額損金 | G15: 1 | H15: 坂本 武 | I15: 90歳まで | J15: 年払 | K15: 5698547 | L15: =IF(J15="月払",K15*12,IF(J15="年払",K15,0)) -> 5698547 | M15: =L15*G15 -> 5698547 | N15: 10,000万円 | O15: 1138 | P15: 0.5 | Q15: 2026年度払済？ | R15: =IF(J15="年払",MONTH(D15),"") -> 6
A16: 12 | B16: 大同生命 | C16: 656-028100-0 | D16: 44765 | E16: 旭土地 | F16: 全額損金 | G16: 1 | H16: Ｔ 岡田 淳 | I16: 90歳まで | J16: 年払 | K16: 1707660 | L16: =IF(J16="月払",K16*12,IF(J16="年払",K16,0)) -> 1707660 | M16: =L16*G16 -> 1707660 | N16: 15,000万円 | O16: 309 | P16: 0.464 | Q16: 2030年度払済？ | R16: =IF(J16="年払",MONTH(D16),"") -> 7
A17: 13 | B17: 日本生命 | D17: 44739 | E17: 旭土地 | F17: 4割損金 | G17: 0.4 | H17: 坂本 信 | I17: 97歳まで | J17: 年払 | K17: 3027080 | L17: =IF(J17="月払",K17*12,IF(J17="年払",K17,0)) -> 3027080 | M17: =L17*G17 -> 1210832 | N17: 14,000万円 | O17: 1250 | P17: 0.826 | Q17: 保有 | R17: =IF(J17="年払",MONTH(D17),"") -> 6 | T17: 元表の記載: 横浜
A18: 14 | B18: 日本生命 | D18: 44832 | E18: 旭土地 | F18: 4割損金 | G18: 0.4 | H18: 坂本 信 | I18: 97歳まで | J18: 年払 | K18: 4973060 | L18: =IF(J18="月払",K18*12,IF(J18="年払",K18,0)) -> 4973060 | M18: =L18*G18 -> 1989224 | N18: 2,300万円 | O18: 1654 | P18: 0.831 | Q18: 保有 | R18: =IF(J18="年払",MONTH(D18),"") -> 9 | T18: 元表の記載: 三菱
A19: 15 | B19: 日本生命 | D19: 45097 | E19: 旭土地 | F19: 4割損金 | G19: 0.4 | H19: 岡田 淳 | I19: 100歳まで | J19: 年払 | K19: 3014812 | L19: =IF(J19="月払",K19*12,IF(J19="年払",K19,0)) -> 3014812 | M19: =L19*G19 -> 1205924.8 | N19: 12,400万円 | O19: 714 | P19: 0.789 | Q19: 保有 | R19: =IF(J19="年払",MONTH(D19),"") -> 6 | T19: 元表の記載: 横浜
A20: 16 | B20: 日本生命 | D20: 45191 | E20: 旭土地 | F20: 4割損金 | G20: 0.4 | H20: 岡田 淳 | I20: 100歳まで | J20: 年払 | K20: 3014812 | L20: =IF(J20="月払",K20*12,IF(J20="年払",K20,0)) -> 3014812 | M20: =L20*G20 -> 1205924.8 | N20: 12,400万円 | O20: 451 | P20: 0.748 | Q20: 保有 | R20: =IF(J20="年払",MONTH(D20),"") -> 9 | T20: 元表の記載: 横浜
A21: 17 | B21: 明治安田 | D21: 44092 | E21: 旭土地 | F21: 新養老保険 | G21: 0.5 | H21: 坂本 武 | I21: 72歳まで | J21: 年払 | K21: 769825 | L21: =IF(J21="月払",K21*12,IF(J21="年払",K21,0)) -> 769825 | M21: =L21*G21 -> 384912.5 | N21: 700万円 | O21: 461 | P21: 0.881 | Q21: 2030年度解約 | R21: =IF(J21="年払",MONTH(D21),"") -> 9 | T21: 元表の記載: 横浜
A22: 18 | B22: 明治安田 | D22: 44090 | E22: 旭土地 | F22: 新養老保険 | G22: 0.5 | H22: 横山 清美 | I22: 67歳まで | J22: 年払 | K22: 746963 | L22: =IF(J22="月払",K22*12,IF(J22="年払",K22,0)) -> 746963 | M22: =L22*G22 -> 373481.5 | N22: 700万円 | O22: 411 | P22: 0.917 | Q22: 2030年度解約 | R22: =IF(J22="年払",MONTH(D22),"") -> 9 | T22: 元表の記載: 横浜
A23: 19 | B23: 大同生命 | D23: 41821 | E23: 旭土地 | F23: 全損 | G23: 0 | H23: 坂本 麻莉 | I23: 70歳まで | J23: 払済 | K23: 0 | L23: =IF(J23="月払",K23*12,IF(J23="年払",K23,0)) -> 0 | M23: =L23*G23 -> 0 | N23: 1,878万円 | O23: 591 | P23: 0.687 | R23: =IF(J23="年払",MONTH(D23),"") | T23: 元表の右端欄(番号欄に「4」と記載)。番号は本表で19・20に付番
A24: 20 | B24: 大同生命 | D24: 41821 | E24: 旭土地 | F24: 全額損金 | G24: 1 | H24: 坂本 麻莉 | I24: 70歳まで | J24: 月払 | K24: 28900 | L24: =IF(J24="月払",K24*12,IF(J24="年払",K24,0)) -> 346800 | M24: =L24*G24 -> 346800 | N24: 10,000万円 | O24: 289 | P24: 0.667 | R24: =IF(J24="年払",MONTH(D24),"") | T24: 元表の右端欄(番号欄に「11」と記載)。番号は本表で19・20に付番
A25: 合計 | K25: =SUMIFS(K5:K24,J5:J24,"月払") -> 892858 | L25: =SUM(L5:L24) -> 33667055 | M25: =SUM(M5:M24) -> 20689164 | O25: =SUM(O5:O24) -> 12057 | T25: K列合計は月払の月額合計
A27: 集計
A28: 月払の月額合計(円) | E28: =SUMIFS(K5:K24,J5:J24,"月払") -> 892858
A29: 年払の年額合計(円) | E29: =SUMIFS(L5:L24,J5:J24,"年払") -> 22952759
A30: 年間保険料合計(円) | E30: =L25 -> 33667055
A31: 年間損金計上額(円) | E31: =M25 -> 20689164
A32: 損金にならない部分(円・資産計上等) | E32: =L25-M25 -> 12977891
A33: 払済・保険料0の契約数 | E33: =COUNTIF(J5:J24,"払済") -> 5
A34: R8年の返戻金合計(万円) | E34: =O25 -> 12057
A36: 元表との照合 | E36: 本表 | F36: 元表 | G36: 差
A37: 月払の月額合計 番号1〜18(元表 863,958円) | E37: =SUMIFS(K5:K22,J5:J22,"月払") -> 863958 | F37: 863958 | G37: =E37-F37 -> 0
A38: 年払 番号11・12(元表 7,406,207円) | E38: =SUMIFS(L15:L16,J15:J16,"年払") -> 7406207 | F38: 7406207 | G38: =E38-F38 -> 0
A39: 年払 番号13〜18(元表 15,546,552円) | E39: =SUMIFS(L17:L22,J17:J22,"年払") -> 15546552 | F39: 15546552 | G39: =E39-F39 -> 0
A40: 損金計上 番号1〜18の合計(元表 20,068,524円) | E40: =SUM(M5:M22)-M9 -> 20068524 | F40: 20068524 | G40: =E40-F40 -> 0
A42: ※元表の損金計上合計は、番号5(医療保険・年27万円)と別枠の番号20(月額28,900円)を含んでいません。本表の「年間損金計上額」にはこの2件を含めています。
A43: ※年払の支払月は加入日の月と仮定しています(会計上の保険料の計上月とおおむね一致)。実際の払込日は保険証券・引落口座で確認してください。
A44: ※「支払停止年月」(黄色)に払済・解約の予定月を入れると、その月以降の支払が保険支払シートから除かれます。空欄=継続。
...

Sheet 返戻金推移
A1: 解約返戻金の推移(万円)・旭土地建物
A2: 出典: 保険一覧ファイル「旭土地 2026.6.10」。各年の返戻金(万円)と返戻率。番号5(医療保険)は元表に推移なし。
A4: 年 | B4: =保険一覧!A5&" "&保険一覧!B5&CHAR(10)&保険一覧!H5 -> 1 大同生命 岡田 優子 | C4: =保険一覧!A6&" "&保険一覧!B6&CHAR(10)&保険一覧!H6 -> 2 大同生命 岡田 淳 | D4: =保険一覧!A7&" "&保険一覧!B7&CHAR(10)&保険一覧!H7 -> 3 大同生命 Ｊ 岡田 優子 | E4: =保険一覧!A8&" "&保険一覧!B8&CHAR(10)&保険一覧!H8 -> 4 大同生命 Ｔ 岡田 優子 | F4: =保険一覧!A9&" "&保険一覧!B9&CHAR(10)&保険一覧!H9 -> 5 大同生命 坂本 武 | G4: =保険一覧!A10&" "&保険一覧!B10&CHAR(10)&保険一覧!H10 -> 6 大同生命 横山 清美 | H4: =保険一覧!A11&" "&保険一覧!B11&CHAR(10)&保険一覧!H11 -> 7 大同生命 坂本 武 | I4: =保険一覧!A12&" "&保険一覧!B12&CHAR(10)&保険一覧!H12 -> 8 大同生命 横山 清美 | J4: =保険一覧!A13&" "&保険一覧!B13&CHAR(10)&保険一覧!H13 -> 9 大同生命 坂本 麻莉 | K4: =保険一覧!A14&" "&保険一覧!B14&CHAR(10)&保険一覧!H14 -> 10 大同生命 坂本 麻莉 | L4: =保険一覧!A15&" "&保険一覧!B15&CHAR(10)&保険一覧!H15 -> 11 大同生命 坂本 武 | M4: =保険一覧!A16&" "&保険一覧!B16&CHAR(10)&保険一覧!H16 -> 12 大同生命 Ｔ 岡田 淳 | N4: =保険一覧!A17&" "&保険一覧!B17&CHAR(10)&保険一覧!H17 -> 13 日本生命 坂本 信 | O4: =保険一覧!A18&" "&保険一覧!B18&CHAR(10)&保険一覧!H18 -> 14 日本生命 坂本 信 | P4: =保険一覧!A19&" "&保険一覧!B19&CHAR(10)&保険一覧!H19 -> 15 日本生命 岡田 淳 | Q4: =保険一覧!A20&" "&保険一覧!B20&CHAR(10)&保険一覧!H20 -> 16 日本生命 岡田 淳 | R4: =保険一覧!A21&" "&保険一覧!B21&CHAR(10)&保険一覧!H21 -> 17 明治安田 坂本 武 | S4: =保険一覧!A22&" "&保険一覧!B22&CHAR(10)&保険一覧!H22 -> 18 明治安田 横山 清美 | T4: =保険一覧!A23&" "&保険一覧!B23&CHAR(10)&保険一覧!H23 -> 19 大同生命 坂本 麻莉 | U4: =保険一覧!A24&" "&保険一覧!B24&CHAR(10)&保険一覧!H24 -> 20 大同生命 坂本 麻莉 | V4: 合計
A5: 2025年 | B5: 159 | C5: 257 | D5: 292 | E5: 167 | G5: 108 | H5: 1839 | I5: 149 | J5: 503 | K5: 116 | L5: 849 | M5: 220 | N5: 982 | O5: 1201 | P5: 451 | Q5: 188 | R5: 384 | S5: 340 | T5: 591 | U5: 267 | V5: =SUM(B5:U5) -> 9063
A6: 2026年 | B6: 165 | C6: 266 | D6: 433 | E6: 241 | G6: 131 | H6: 2247 | I6: 196 | J6: 654 | K6: 456 | L6: 1138 | M6: 309 | N6: 1250 | O6: 1654 | P6: 714 | Q6: 451 | R6: 461 | S6: 411 | T6: 591 | U6: 289 | V6: =SUM(B6:U6) -> 12057
A7: 2027年 | B7: 165 | C7: 267 | D7: 434 | E7: 316 | G7: 154 | H7: 2651 | I7: 242 | J7: 800 | K7: 196 | L7: 1422 | M7: 399 | N7: 1516 | O7: 2114 | P7: 975 | Q7: 714 | R7: 538 | S7: 482 | T7: 590 | U7: 310 | V7: =SUM(B7:U7) -> 14285
A8: 2028年 | B8: 166 | C8: 270 | D8: 434 | E8: 389 | G8: 176 | H8: 3049 | I8: 287 | J8: 944 | K8: 236 | L8: 1701 | M8: 488 | N8: 1780 | O8: 2578 | P8: 1238 | Q8: 975 | R8: 615 | S8: 554 | T8: 589 | U8: 331 | V8: =SUM(B8:U8) -> 16800
A9: 2029年 | B9: 166 | C9: 271 | D9: 435 | E9: 462 | G9: 198 | H9: 3442 | I9: 333 | J9: 1083 | K9: 276 | L9: 1974 | M9: 577 | N9: 2046 | O9: 3044 | P9: 1500 | Q9: 1238 | R9: 692 | S9: 626 | T9: 586 | U9: 351 | V9: =SUM(B9:U9) -> 19300
A10: 2030年 | B10: 167 | C10: 272 | D10: 435 | E10: 535 | G10: 217 | H10: 3828 | I10: 377 | J10: 1220 | K10: 316 | L10: 2238 | M10: 667 | N10: 2311 | O10: 3518 | P10: 1760 | Q10: 1500 | R10: 769 | S10: 700 | T10: 584 | U10: 371 | V10: =SUM(B10:U10) -> 21785
A11: 2031年 | B11: 167 | C11: 273 | D11: 435 | E11: 608 | G11: 235 | H11: 4193 | I11: 421 | J11: 1354 | K11: 356 | L11: 2494 | M11: 756 | N11: 2576 | O11: 3995 | P11: 2022 | Q11: 1760 | T11: 580 | U11: 390 | V11: =SUM(B11:U11) -> 22615
A12: 2032年 | B12: 168 | C12: 274 | D12: 435 | E12: 680 | G12: 250 | H12: 4533 | I12: 464 | J12: 1484 | K12: 395 | L12: 2740 | M12: 845 | N12: 2832 | O12: 4479 | P12: 2281 | Q12: 2022 | T12: 576 | U12: 409 | V12: =SUM(B12:U12) -> 24867
A13: 2033年 | B13: 168 | C13: 275 | D13: 435 | E13: 747 | G13: 262 | H13: 4861 | I13: 505 | J13: 1607 | K13: 433 | L13: 2947 | M13: 930 | N13: 3088 | O13: 4956 | P13: 2540 | Q13: 2281 | T13: 570 | U13: 427 | V13: =SUM(B13:U13) -> 27032
A14: 2034年 | B14: 169 | C14: 276 | D14: 435 | E14: 814 | G14: 272 | H14: 5175 | I14: 544 | J14: 1728 | K14: 471 | L14: 3138 | M14: 1015 | N14: 3341 | O14: 5440 | P14: 2791 | Q14: 2540 | T14: 564 | U14: 443 | V14: =SUM(B14:U14) -> 29156
A15: 2035年 | B15: 169 | C15: 277 | D15: 434 | E15: 880 | G15: 280 | H15: 5473 | I15: 582 | J15: 1845 | K15: 508 | L15: 3310 | M15: 1098 | N15: 3595 | O15: 5926 | P15: 3041 | Q15: 2791 | T15: 557 | U15: 458 | V15: =SUM(B15:U15) -> 31224
A17: 返戻率(R8年) | B17: 0.432 | C17: 0.458 | D17: 0.528 | E17: 0.449 | G17: 0.4 | H17: 0.688 | I17: 0.688 | J17: 0.675 | K17: 0.646 | L17: 0.5 | M17: 0.464 | N17: 0.826 | O17: 0.831 | P17: 0.789 | Q17: 0.748 | R17: 0.881 | S17: 0.917 | T17: 0.687 | U17: 0.667
A18: 意向 | B18: 随時解約検討 | C18: 随時解約検討 | D18: 2027年度払済？ | E18: 2030年度払済？ | F18: 保有 | G18: 保有 | H18: 2027年度払済？ | I18: 保有 | J18: 2027年度払済？ | K18: 保有 | L18: 2026年度払済？ | M18: 2030年度払済？ | N18: 保有 | O18: 保有 | P18: 保有 | Q18: 保有 | R18: 2030年度解約 | S18: 2030年度解約
A20: ※返戻金は各年の見込額(万円)。合計は期間満了済みの契約が抜けるため、年が進むと減る箇所があります。解約時の課税関係(返戻金−資産計上額)は税理士に確認してください。

Sheet 保険支払
A1: 保険料の支払カレンダー(現金ベース・円)
A2: 保険一覧の払込方法・保険料から月別に展開。月払=毎月、年払=加入日の月、払済=0。支払停止年月(保険一覧のS列)を入れるとその月以降は0になります。
A4: 番号・保険会社・被保険者 | C4: 46296 | D4: =EDATE(C4,1) -> 46327 | E4: =EDATE(D4,1) -> 46357 | F4: =EDATE(E4,1) -> 46388 | G4: =EDATE(F4,1) -> 46419 | H4: =EDATE(G4,1) -> 46447 | I4: =EDATE(H4,1) -> 46478 | J4: =EDATE(I4,1) -> 46508 | K4: =EDATE(J4,1) -> 46539 | ... T4: =EDATE(S4,1) -> 46813 | U4: 期間計 | V4: 令和9年度計 (R9/4〜R10/3)
A6: =保険一覧!A5&" "&保険一覧!B5&" "&保険一覧!H5 -> 1 大同生命 岡田 優子 | C6: =IF(OR(保険一覧!$S5="",C$4<保険一覧!$S5),IF(保険一覧!$J5="月払",保険一覧!$K5,IF(AND(保険一覧!$J5="年払",MONTH(C$4)=保険一覧!$R5),保険一覧!$K5,0)),0) -> 0 | D6: =IF(OR(保険一覧!$S5="",D$4<保険一覧!$S5),IF(保険一覧!$J5="月払",保険一覧!$K5,IF(AND(保険一覧!$J5="年払",MONTH(D$4)=保険一覧!$R5),保険一覧!$K5,0)),0) -> 0 | E6: =IF(OR(保険一覧!$S5="",E$4<保険一覧!$S5),IF(保険一覧!$J5="月払",保険一覧!$K5,IF(AND(保険一覧!$J5="年払",MONTH(E$4)=保険一覧!$R5),保険一覧!$K5,0)),0) -> 0 | F6: =IF(OR(保険一覧!$S5="",F$4<保険一覧!$S5),IF(保険一覧!$J5="月払",保険一覧!$K5,IF(AND(保険一覧!$J5="年払",MONTH(F$4)=保険一覧!$R5),保険一覧!$K5,0)),0) -> 0 | G6: =IF(OR(保険一覧!$S5="",G$4<保険一覧!$S5),IF(保険一覧!$J5="月払",保険一覧!$K5,IF(AND(保険一覧!$J5="年払",MONTH(G$4)=保険一覧!$R5),保険一覧!$K5,0)),0) -> 0 | H6: =IF(OR(保険一覧!$S5="",H$4<保険一覧!$S5),IF(保険一覧!$J5="月払",保険一覧!$K5,IF(AND(保険一覧!$J5="年払",MONTH(H$4)=保険一覧!$R5),保険一覧!$K5,0)),0) -> 0 | I6: =IF(OR(保険一覧!$S5="",I$4<保険一覧!$S5),IF(保険一覧!$J5="月払",保険一覧!$K5,IF(AND(保険一覧!$J5="年払",MONTH(I$4)=保険一覧!$R5),保険一覧!$K5,0)),0) -> 0 | J6: =IF(OR(保険一覧!$S5="",J$4<保険一覧!$S5),IF(保険一覧!$J5="月払",保険一覧!$K5,IF(AND(保険一覧!$J5="年払",MONTH(J$4)=保険一覧!$R5),保険一覧!$K5,0)),0) -> 0 | ... T6: =IF(OR(保険一覧!$S5="",T$4<保険一覧!$S5),IF(保険一覧!$J5="月払",保険一覧!$K5,IF(AND(保険一覧!$J5="年払",MONTH(T$4)=保険一覧!$R5),保険一覧!$K5,0)),0) -> 0 | U6: =SUM(C6:T6) -> 0 | V6: =SUMIFS(C6:T6,$C$4:$T$4,">="&DATE(2027,4,1),$C$4:$T$4,"<="&DATE(2028,3,1)) -> 0
A7: =保険一覧!A6&" "&保険一覧!B6&" "&保険一覧!H6 -> 2 大同生命 岡田 淳 | C7: =IF(OR(保険一覧!$S6="",C$4<保険一覧!$S6),IF(保険一覧!$J6="月払",保険一覧!$K6,IF(AND(保険一覧!$J6="年払",MONTH(C$4)=保険一覧!$R6),保険一覧!$K6,0)),0) -> 0 | D7: =IF(OR(保険一覧!$S6="",D$4<保険一覧!$S6),IF(保険一覧!$J6="月払",保険一覧!$K6,IF(AND(保険一覧!$J6="年払",MONTH(D$4)=保険一覧!$R6),保険一覧!$K6,0)),0) -> 0 | E7: =IF(OR(保険一覧!$S6="",E$4<保険一覧!$S6),IF(保険一覧!$J6="月払",保険一覧!$K6,IF(AND(保険一覧!$J6="年払",MONTH(E$4)=保険一覧!$R6),保険一覧!$K6,0)),0) -> 0 | F7: =IF(OR(保険一覧!$S6="",F$4<保険一覧!$S6),IF(保険一覧!$J6="月払",保険一覧!$K6,IF(AND(保険一覧!$J6="年払",MONTH(F$4)=保険一覧!$R6),保険一覧!$K6,0)),0) -> 0 | G7: =IF(OR(保険一覧!$S6="",G$4<保険一覧!$S6),IF(保険一覧!$J6="月払",保険一覧!$K6,IF(AND(保険一覧!$J6="年払",MONTH(G$4)=保険一覧!$R6),保険一覧!$K6,0)),0) -> 0 | H7: =IF(OR(保険一覧!$S6="",H$4<保険一覧!$S6),IF(保険一覧!$J6="月払",保険一覧!$K6,IF(AND(保険一覧!$J6="年払",MONTH(H$4)=保険一覧!$R6),保険一覧!$K6,0)),0) -> 0 | I7: =IF(OR(保険一覧!$S6="",I$4<保険一覧!$S6),IF(保険一覧!$J6="月払",保険一覧!$K6,IF(AND(保険一覧!$J6="年払",MONTH(I$4)=保険一覧!$R6),保険一覧!$K6,0)),0) -> 0 | J7: =IF(OR(保険一覧!$S6="",J$4<保険一覧!$S6),IF(保険一覧!$J6="月払",保険一覧!$K6,IF(AND(保険一覧!$J6="年払",MONTH(J$4)=保険一覧!$R6),保険一覧!$K6,0)),0) -> 0 | ... T7: =IF(OR(保険一覧!$S6="",T$4<保険一覧!$S6),IF(保険一覧!$J6="月払",保険一覧!$K6,IF(AND(保険一覧!$J6="年払",MONTH(T$4)=保険一覧!$R6),保険一覧!$K6,0)),0) -> 0 | U7: =SUM(C7:T7) -> 0 | V7: =SUMIFS(C7:T7,$C$4:$T$4,">="&DATE(2027,4,1),$C$4:$T$4,"<="&DATE(2028,3,1)) -> 0
A8: =保険一覧!A7&" "&保険一覧!B7&" "&保険一覧!H7 -> 3 大同生命 Ｊ 岡田 優子 | C8: =IF(OR(保険一覧!$S7="",C$4<保険一覧!$S7),IF(保険一覧!$J7="月払",保険一覧!$K7,IF(AND(保険一覧!$J7="年払",MONTH(C$4)=保険一覧!$R7),保険一覧!$K7,0)),0) -> 0 | D8: =IF(OR(保険一覧!$S7="",D$4<保険一覧!$S7),IF(保険一覧!$J7="月払",保険一覧!$K7,IF(AND(保険一覧!$J7="年払",MONTH(D$4)=保険一覧!$R7),保険一覧!$K7,0)),0) -> 0 | E8: =IF(OR(保険一覧!$S7="",E$4<保険一覧!$S7),IF(保険一覧!$J7="月払",保険一覧!$K7,IF(AND(保険一覧!$J7="年払",MONTH(E$4)=保険一覧!$R7),保険一覧!$K7,0)),0) -> 0 | F8: =IF(OR(保険一覧!$S7="",F$4<保険一覧!$S7),IF(保険一覧!$J7="月払",保険一覧!$K7,IF(AND(保険一覧!$J7="年払",MONTH(F$4)=保険一覧!$R7),保険一覧!$K7,0)),0) -> 0 | G8: =IF(OR(保険一覧!$S7="",G$4<保険一覧!$S7),IF(保険一覧!$J7="月払",保険一覧!$K7,IF(AND(保険一覧!$J7="年払",MONTH(G$4)=保険一覧!$R7),保険一覧!$K7,0)),0) -> 0 | H8: =IF(OR(保険一覧!$S7="",H$4<保険一覧!$S7),IF(保険一覧!$J7="月払",保険一覧!$K7,IF(AND(保険一覧!$J7="年払",MONTH(H$4)=保険一覧!$R7),保険一覧!$K7,0)),0) -> 0 | I8: =IF(OR(保険一覧!$S7="",I$4<保険一覧!$S7),IF(保険一覧!$J7="月払",保険一覧!$K7,IF(AND(保険一覧!$J7="年払",MONTH(I$4)=保険一覧!$R7),保険一覧!$K7,0)),0) -> 0 | J8: =IF(OR(保険一覧!$S7="",J$4<保険一覧!$S7),IF(保険一覧!$J7="月払",保険一覧!$K7,IF(AND(保険一覧!$J7="年払",MONTH(J$4)=保険一覧!$R7),保険一覧!$K7,0)),0) -> 0 | ... T8: =IF(OR(保険一覧!$S7="",T$4<保険一覧!$S7),IF(保険一覧!$J7="月払",保険一覧!$K7,IF(AND(保険一覧!$J7="年払",MONTH(T$4)=保険一覧!$R7),保険一覧!$K7,0)),0) -> 0 | U8: =SUM(C8:T8) -> 0 | V8: =SUMIFS(C8:T8,$C$4:$T$4,">="&DATE(2027,4,1),$C$4:$T$4,"<="&DATE(2028,3,1)) -> 0
A9: =保険一覧!A8&" "&保険一覧!B8&" "&保険一覧!H8 -> 4 大同生命 Ｔ 岡田 優子 | C9: =IF(OR(保険一覧!$S8="",C$4<保険一覧!$S8),IF(保険一覧!$J8="月払",保険一覧!$K8,IF(AND(保険一覧!$J8="年払",MONTH(C$4)=保険一覧!$R8),保険一覧!$K8,0)),0) -> 0 | D9: =IF(OR(保険一覧!$S8="",D$4<保険一覧!$S8),IF(保険一覧!$J8="月払",保険一覧!$K8,IF(AND(保険一覧!$J8="年払",MONTH(D$4)=保険一覧!$R8),保険一覧!$K8,0)),0) -> 0 | E9: =IF(OR(保険一覧!$S8="",E$4<保険一覧!$S8),IF(保険一覧!$J8="月払",保険一覧!$K8,IF(AND(保険一覧!$J8="年払",MONTH(E$4)=保険一覧!$R8),保険一覧!$K8,0)),0) -> 0 | F9: =IF(OR(保険一覧!$S8="",F$4<保険一覧!$S8),IF(保険一覧!$J8="月払",保険一覧!$K8,IF(AND(保険一覧!$J8="年払",MONTH(F$4)=保険一覧!$R8),保険一覧!$K8,0)),0) -> 0 | G9: =IF(OR(保険一覧!$S8="",G$4<保険一覧!$S8),IF(保険一覧!$J8="月払",保険一覧!$K8,IF(AND(保険一覧!$J8="年払",MONTH(G$4)=保険一覧!$R8),保険一覧!$K8,0)),0) -> 0 | H9: =IF(OR(保険一覧!$S8="",H$4<保険一覧!$S8),IF(保険一覧!$J8="月払",保険一覧!$K8,IF(AND(保険一覧!$J8="年払",MONTH(H$4)=保険一覧!$R8),保険一覧!$K8,0)),0) -> 0 | I9: =IF(OR(保険一覧!$S8="",I$4<保険一覧!$S8),IF(保険一覧!$J8="月払",保険一覧!$K8,IF(AND(保険一覧!$J8="年払",MONTH(I$4)=保険一覧!$R8),保険一覧!$K8,0)),0) -> 0 | J9: =IF(OR(保険一覧!$S8="",J$4<保険一覧!$S8),IF(保険一覧!$J8="月払",保険一覧!$K8,IF(AND(保険一覧!$J8="年払",MONTH(J$4)=保険一覧!$R8),保険一覧!$K8,0)),0) -> 0 | ... T9: =IF(OR(保険一覧!$S8="",T$4<保険一覧!$S8),IF(保険一覧!$J8="月払",保険一覧!$K8,IF(AND(保険一覧!$J8="年払",MONTH(T$4)=保険一覧!$R8),保険一覧!$K8,0)),0) -> 0 | U9: =SUM(C9:T9) -> 0 | V9: =SUMIFS(C9:T9,$C$4:$T$4,">="&DATE(2027,4,1),$C$4:$T$4,"<="&DATE(2028,3,1)) -> 0
A10: =保険一覧!A9&" "&保険一覧!B9&" "&保険一覧!H9 -> 5 大同生命 坂本 武 | C10: =IF(OR(保険一覧!$S9="",C$4<保険一覧!$S9),IF(保険一覧!$J9="月払",保険一覧!$K9,IF(AND(保険一覧!$J9="年払",MONTH(C$4)=保険一覧!$R9),保険一覧!$K9,0)),0) -> 22820 | D10: =IF(OR(保険一覧!$S9="",D$4<保険一覧!$S9),IF(保険一覧!$J9="月払",保険一覧!$K9,IF(AND(保険一覧!$J9="年払",MONTH(D$4)=保険一覧!$R9),保険一覧!$K9,0)),0) -> 22820 | E10: =IF(OR(保険一覧!$S9="",E$4<保険一覧!$S9),IF(保険一覧!$J9="月払",保険一覧!$K9,IF(AND(保険一覧!$J9="年払",MONTH(E$4)=保険一覧!$R9),保険一覧!$K9,0)),0) -> 22820 | F10: =IF(OR(保険一覧!$S9="",F$4<保険一覧!$S9),IF(保険一覧!$J9="月払",保険一覧!$K9,IF(AND(保険一覧!$J9="年払",MONTH(F$4)=保険一覧!$R9),保険一覧!$K9,0)),0) -> 22820 | G10: =IF(OR(保険一覧!$S9="",G$4<保険一覧!$S9),IF(保険一覧!$J9="月払",保険一覧!$K9,IF(AND(保険一覧!$J9="年払",MONTH(G$4)=保険一覧!$R9),保険一覧!$K9,0)),0) -> 22820 | H10: =IF(OR(保険一覧!$S9="",H$4<保険一覧!$S9),IF(保険一覧!$J9="月払",保険一覧!$K9,IF(AND(保険一覧!$J9="年払",MONTH(H$4)=保険一覧!$R9),保険一覧!$K9,0)),0) -> 22820 | I10: =IF(OR(保険一覧!$S9="",I$4<保険一覧!$S9),IF(保険一覧!$J9="月払",保険一覧!$K9,IF(AND(保険一覧!$J9="年払",MONTH(I$4)=保険一覧!$R9),保険一覧!$K9,0)),0) -> 22820 | J10: =IF(OR(保険一覧!$S9="",J$4<保険一覧!$S9),IF(保険一覧!$J9="月払",保険一覧!$K9,IF(AND(保険一覧!$J9="年払",MONTH(J$4)=保険一覧!$R9),保険一覧!$K9,0)),0) -> 22820 | ... T10: =IF(OR(保険一覧!$S9="",T$4<保険一覧!$S9),IF(保険一覧!$J9="月払",保険一覧!$K9,IF(AND(保険一覧!$J9="年払",MONTH(T$4)=保険一覧!$R9),保険一覧!$K9,0)),0) -> 22820 | U10: =SUM(C10:T10) -> 410760 | V10: =SUMIFS(C10:T10,$C$4:$T$4,">="&DATE(2027,4,1),$C$4:$T$4,"<="&DATE(2028,3,1)) -> 273840
A11: =保険一覧!A10&" "&保険一覧!B10&" "&保険一覧!H10 -> 6 大同生命 横山 清美 | C11: =IF(OR(保険一覧!$S10="",C$4<保険一覧!$S10),IF(保険一覧!$J10="月払",保険一覧!$K10,IF(AND(保険一覧!$J10="年払",MONTH(C$4)=保険一覧!$R10),保険一覧!$K10,0)),0) -> 49130 | D11: =IF(OR(保険一覧!$S10="",D$4<保険一覧!$S10),IF(保険一覧!$J10="月払",保険一覧!$K10,IF(AND(保険一覧!$J10="年払",MONTH(D$4)=保険一覧!$R10),保険一覧!$K10,0)),0) -> 49130 | E11: =IF(OR(保険一覧!$S10="",E$4<保険一覧!$S10),IF(保険一覧!$J10="月払",保険一覧!$K10,IF(AND(保険一覧!$J10="年払",MONTH(E$4)=保険一覧!$R10),保険一覧!$K10,0)),0) -> 49130 | F11: =IF(OR(保険一覧!$S10="",F$4<保険一覧!$S10),IF(保険一覧!$J10="月払",保険一覧!$K10,IF(AND(保険一覧!$J10="年払",MONTH(F$4)=保険一覧!$R10),保険一覧!$K10,0)),0) -> 49130 | G11: =IF(OR(保険一覧!$S10="",G$4<保険一覧!$S10),IF(保険一覧!$J10="月払",保険一覧!$K10,IF(AND(保険一覧!$J10="年払",MONTH(G$4)=保険一覧!$R10),保険一覧!$K10,0)),0) -> 49130 | H11: =IF(OR(保険一覧!$S10="",H$4<保険一覧!$S10),IF(保険一覧!$J10="月払",保険一覧!$K10,IF(AND(保険一覧!$J10="年払",MONTH(H$4)=保険一覧!$R10),保険一覧!$K10,0)),0) -> 49130 | I11: =IF(OR(保険一覧!$S10="",I$4<保険一覧!$S10),IF(保険一覧!$J10="月払",保険一覧!$K10,IF(AND(保険一覧!$J10="年払",MONTH(I$4)=保険一覧!$R10),保険一覧!$K10,0)),0) -> 49130 | J11: =IF(OR(保険一覧!$S10="",J$4<保険一覧!$S10),IF(保険一覧!$J10="月払",保険一覧!$K10,IF(AND(保険一覧!$J10="年払",MONTH(J$4)=保険一覧!$R10),保険一覧!$K10,0)),0) -> 49130 | ... T11: =IF(OR(保険一覧!$S10="",T$4<保険一覧!$S10),IF(保険一覧!$J10="月払",保険一覧!$K10,IF(AND(保険一覧!$J10="年払",MONTH(T$4)=保険一覧!$R10),保険一覧!$K10,0)),0) -> 49130 | U11: =SUM(C11:T11) -> 884340 | V11: =SUMIFS(C11:T11,$C$4:$T$4,">="&DATE(2027,4,1),$C$4:$T$4,"<="&DATE(2028,3,1)) -> 589560
A12: =保険一覧!A11&" "&保険一覧!B11&" "&保険一覧!H11 -> 7 大同生命 坂本 武 | C12: =IF(OR(保険一覧!$S11="",C$4<保険一覧!$S11),IF(保険一覧!$J11="月払",保険一覧!$K11,IF(AND(保険一覧!$J11="年払",MONTH(C$4)=保険一覧!$R11),保険一覧!$K11,0)),0) -> 505120 | D12: =IF(OR(保険一覧!$S11="",D$4<保険一覧!$S11),IF(保険一覧!$J11="月払",保険一覧!$K11,IF(AND(保険一覧!$J11="年払",MONTH(D$4)=保険一覧!$R11),保険一覧!$K11,0)),0) -> 505120 | E12: =IF(OR(保険一覧!$S11="",E$4<保険一覧!$S11),IF(保険一覧!$J11="月払",保険一覧!$K11,IF(AND(保険一覧!$J11="年払",MONTH(E$4)=保険一覧!$R11),保険一覧!$K11,0)),0) -> 505120 | F12: =IF(OR(保険一覧!$S11="",F$4<保険一覧!$S11),IF(保険一覧!$J11="月払",保険一覧!$K11,IF(AND(保険一覧!$J11="年払",MONTH(F$4)=保険一覧!$R11),保険一覧!$K11,0)),0) -> 505120 | G12: =IF(OR(保険一覧!$S11="",G$4<保険一覧!$S11),IF(保険一覧!$J11="月払",保険一覧!$K11,IF(AND(保険一覧!$J11="年払",MONTH(G$4)=保険一覧!$R11),保険一覧!$K11,0)),0) -> 505120 | H12: =IF(OR(保険一覧!$S11="",H$4<保険一覧!$S11),IF(保険一覧!$J11="月払",保険一覧!$K11,IF(AND(保険一覧!$J11="年払",MONTH(H$4)=保険一覧!$R11),保険一覧!$K11,0)),0) -> 505120 | I12: =IF(OR(保険一覧!$S11="",I$4<保険一覧!$S11),IF(保険一覧!$J11="月払",保険一覧!$K11,IF(AND(保険一覧!$J11="年払",MONTH(I$4)=保険一覧!$R11),保険一覧!$K11,0)),0) -> 505120 | J12: =IF(OR(保険一覧!$S11="",J$4<保険一覧!$S11),IF(保険一覧!$J11="月払",保険一覧!$K11,IF(AND(保険一覧!$J11="年払",MONTH(J$4)=保険一覧!$R11),保険一覧!$K11,0)),0) -> 505120 | ... T12: =IF(OR(保険一覧!$S11="",T$4<保険一覧!$S11),IF(保険一覧!$J11="月払",保険一覧!$K11,IF(AND(保険一覧!$J11="年払",MONTH(T$4)=保険一覧!$R11),保険一覧!$K11,0)),0) -> 505120 | U12: =SUM(C12:T12) -> 9092160 | V12: =SUMIFS(C12:T12,$C$4:$T$4,">="&DATE(2027,4,1),$C$4:$T$4,"<="&DATE(2028,3,1)) -> 6061440
A13: =保険一覧!A12&" "&保険一覧!B12&" "&保険一覧!H12 -> 8 大同生命 横山 清美 | C13: =IF(OR(保険一覧!$S12="",C$4<保険一覧!$S12),IF(保険一覧!$J12="月払",保険一覧!$K12,IF(AND(保険一覧!$J12="年払",MONTH(C$4)=保険一覧!$R12),保険一覧!$K12,0)),0) -> 57687 | D13: =IF(OR(保険一覧!$S12="",D$4<保険一覧!$S12),IF(保険一覧!$J12="月払",保険一覧!$K12,IF(AND(保険一覧!$J12="年払",MONTH(D$4)=保険一覧!$R12),保険一覧!$K12,0)),0) -> 57687 | E13: =IF(OR(保険一覧!$S12="",E$4<保険一覧!$S12),IF(保険一覧!$J12="月払",保険一覧!$K12,IF(AND(保険一覧!$J12="年払",MONTH(E$4)=保険一覧!$R12),保険一覧!$K12,0)),0) -> 57687 | F13: =IF(OR(保険一覧!$S12="",F$4<保険一覧!$S12),IF(保険一覧!$J12="月払",保険一覧!$K12,IF(AND(保険一覧!$J12="年払",MONTH(F$4)=保険一覧!$R12),保険一覧!$K12,0)),0) -> 57687 | G13: =IF(OR(保険一覧!$S12="",G$4<保険一覧!$S12),IF(保険一覧!$J12="月払",保険一覧!$K12,IF(AND(保険一覧!$J12="年払",MONTH(G$4)=保険一覧!$R12),保険一覧!$K12,0)),0) -> 57687 | H13: =IF(OR(保険一覧!$S12="",H$4<保険一覧!$S12),IF(保険一覧!$J12="月払",保険一覧!$K12,IF(AND(保険一覧!$J12="年払",MONTH(H$4)=保険一覧!$R12),保険一覧!$K12,0)),0) -> 57687 | I13: =IF(OR(保険一覧!$S12="",I$4<保険一覧!$S12),IF(保険一覧!$J12="月払",保険一覧!$K12,IF(AND(保険一覧!$J12="年払",MONTH(I$4)=保険一覧!$R12),保険一覧!$K12,0)),0) -> 57687 | J13: =IF(OR(保険一覧!$S12="",J$4<保険一覧!$S12),IF(保険一覧!$J12="月払",保険一覧!$K12,IF(AND(保険一覧!$J12="年払",MONTH(J$4)=保険一覧!$R12),保険一覧!$K12,0)),0) -> 57687 | ... T13: =IF(OR(保険一覧!$S12="",T$4<保険一覧!$S12),IF(保険一覧!$J12="月払",保険一覧!$K12,IF(AND(保険一覧!$J12="年払",MONTH(T$4)=保険一覧!$R12),保険一覧!$K12,0)),0) -> 57687 | U13: =SUM(C13:T13) -> 1038366 | V13: =SUMIFS(C13:T13,$C$4:$T$4,">="&DATE(2027,4,1),$C$4:$T$4,"<="&DATE(2028,3,1)) -> 692244
A14: =保険一覧!A13&" "&保険一覧!B13&" "&保険一覧!H13 -> 9 大同生命 坂本 麻莉 | C14: =IF(OR(保険一覧!$S13="",C$4<保険一覧!$S13),IF(保険一覧!$J13="月払",保険一覧!$K13,IF(AND(保険一覧!$J13="年払",MONTH(C$4)=保険一覧!$R13),保険一覧!$K13,0)),0) -> 179573 | D14: =IF(OR(保険一覧!$S13="",D$4<保険一覧!$S13),IF(保険一覧!$J13="月払",保険一覧!$K13,IF(AND(保険一覧!$J13="年払",MONTH(D$4)=保険一覧!$R13),保険一覧!$K13,0)),0) -> 179573 | E14: =IF(OR(保険一覧!$S13="",E$4<保険一覧!$S13),IF(保険一覧!$J13="月払",保険一覧!$K13,IF(AND(保険一覧!$J13="年払",MONTH(E$4)=保険一覧!$R13),保険一覧!$K13,0)),0) -> 179573 | F14: =IF(OR(保険一覧!$S13="",F$4<保険一覧!$S13),IF(保険一覧!$J13="月払",保険一覧!$K13,IF(AND(保険一覧!$J13="年払",MONTH(F$4)=保険一覧!$R13),保険一覧!$K13,0)),0) -> 179573 | G14: =IF(OR(保険一覧!$S13="",G$4<保険一覧!$S13),IF(保険一覧!$J13="月払",保険一覧!$K13,IF(AND(保険一覧!$J13="年払",MONTH(G$4)=保険一覧!$R13),保険一覧!$K13,0)),0) -> 179573 | H14: =IF(OR(保険一覧!$S13="",H$4<保険一覧!$S13),IF(保険一覧!$J13="月払",保険一覧!$K13,IF(AND(保険一覧!$J13="年払",MONTH(H$4)=保険一覧!$R13),保険一覧!$K13,0)),0) -> 179573 | I14: =IF(OR(保険一覧!$S13="",I$4<保険一覧!$S13),IF(保険一覧!$J13="月払",保険一覧!$K13,IF(AND(保険一覧!$J13="年払",MONTH(I$4)=保険一覧!$R13),保険一覧!$K13,0)),0) -> 179573 | J14: =IF(OR(保険一覧!$S13="",J$4<保険一覧!$S13),IF(保険一覧!$J13="月払",保険一覧!$K13,IF(AND(保険一覧!$J13="年払",MONTH(J$4)=保険一覧!$R13),保険一覧!$K13,0)),0) -> 179573 | ... T14: =IF(OR(保険一覧!$S13="",T$4<保険一覧!$S13),IF(保険一覧!$J13="月払",保険一覧!$K13,IF(AND(保険一覧!$J13="年払",MONTH(T$4)=保険一覧!$R13),保険一覧!$K13,0)),0) -> 179573 | U14: =SUM(C14:T14) -> 3232314 | V14: =SUMIFS(C14:T14,$C$4:$T$4,">="&DATE(2027,4,1),$C$4:$T$4,"<="&DATE(2028,3,1)) -> 2154876
A15: =保険一覧!A14&" "&保険一覧!B14&" "&保険一覧!H14 -> 10 大同生命 坂本 麻莉 | C15: =IF(OR(保険一覧!$S14="",C$4<保険一覧!$S14),IF(保険一覧!$J14="月払",保険一覧!$K14,IF(AND(保険一覧!$J14="年払",MONTH(C$4)=保険一覧!$R14),保険一覧!$K14,0)),0) -> 49628 | D15: =IF(OR(保険一覧!$S14="",D$4<保険一覧!$S14),IF(保険一覧!$J14="月払",保険一覧!$K14,IF(AND(保険一覧!$J14="年払",MONTH(D$4)=保険一覧!$R14),保険一覧!$K14,0)),0) -> 49628 | E15: =IF(OR(保険一覧!$S14="",E$4<保険一覧!$S14),IF(保険一覧!$J14="月払",保険一覧!$K14,IF(AND(保険一覧!$J14="年払",MONTH(E$4)=保険一覧!$R14),保険一覧!$K14,0)),0) -> 49628 | F15: =IF(OR(保険一覧!$S14="",F$4<保険一覧!$S14),IF(保険一覧!$J14="月払",保険一覧!$K14,IF(AND(保険一覧!$J14="年払",MONTH(F$4)=保険一覧!$R14),保険一覧!$K14,0)),0) -> 49628 | G15: =IF(OR(保険一覧!$S14="",G$4<保険一覧!$S14),IF(保険一覧!$J14="月払",保険一覧!$K14,IF(AND(保険一覧!$J14="年払",MONTH(G$4)=保険一覧!$R14),保険一覧!$K14,0)),0) -> 49628 | H15: =IF(OR(保険一覧!$S14="",H$4<保険一覧!$S14),IF(保険一覧!$J14="月払",保険一覧!$K14,IF(AND(保険一覧!$J14="年払",MONTH(H$4)=保険一覧!$R14),保険一覧!$K14,0)),0) -> 49628 | I15: =IF(OR(保険一覧!$S14="",I$4<保険一覧!$S14),IF(保険一覧!$J14="月払",保険一覧!$K14,IF(AND(保険一覧!$J14="年払",MONTH(I$4)=保険一覧!$R14),保険一覧!$K14,0)),0) -> 49628 | J15: =IF(OR(保険一覧!$S14="",J$4<保険一覧!$S14),IF(保険一覧!$J14="月払",保険一覧!$K14,IF(AND(保険一覧!$J14="年払",MONTH(J$4)=保険一覧!$R14),保険一覧!$K14,0)),0) -> 49628 | ... T15: =IF(OR(保険一覧!$S14="",T$4<保険一覧!$S14),IF(保険一覧!$J14="月払",保険一覧!$K14,IF(AND(保険一覧!$J14="年払",MONTH(T$4)=保険一覧!$R14),保険一覧!$K14,0)),0) -> 49628 | U15: =SUM(C15:T15) -> 893304 | V15: =SUMIFS(C15:T15,$C$4:$T$4,">="&DATE(2027,4,1),$C$4:$T$4,"<="&DATE(2028,3,1)) -> 595536
A16: =保険一覧!A15&" "&保険一覧!B15&" "&保険一覧!H15 -> 11 大同生命 坂本 武 | C16: =IF(OR(保険一覧!$S15="",C$4<保険一覧!$S15),IF(保険一覧!$J15="月払",保険一覧!$K15,IF(AND(保険一覧!$J15="年払",MONTH(C$4)=保険一覧!$R15),保険一覧!$K15,0)),0) -> 0 | D16: =IF(OR(保険一覧!$S15="",D$4<保険一覧!$S15),IF(保険一覧!$J15="月払",保険一覧!$K15,IF(AND(保険一覧!$J15="年払",MONTH(D$4)=保険一覧!$R15),保険一覧!$K15,0)),0) -> 0 | E16: =IF(OR(保険一覧!$S15="",E$4<保険一覧!$S15),IF(保険一覧!$J15="月払",保険一覧!$K15,IF(AND(保険一覧!$J15="年払",MONTH(E$4)=保険一覧!$R15),保険一覧!$K15,0)),0) -> 0 | F16: =IF(OR(保険一覧!$S15="",F$4<保険一覧!$S15),IF(保険一覧!$J15="月払",保険一覧!$K15,IF(AND(保険一覧!$J15="年払",MONTH(F$4)=保険一覧!$R15),保険一覧!$K15,0)),0) -> 0 | G16: =IF(OR(保険一覧!$S15="",G$4<保険一覧!$S15),IF(保険一覧!$J15="月払",保険一覧!$K15,IF(AND(保険一覧!$J15="年払",MONTH(G$4)=保険一覧!$R15),保険一覧!$K15,0)),0) -> 0 | H16: =IF(OR(保険一覧!$S15="",H$4<保険一覧!$S15),IF(保険一覧!$J15="月払",保険一覧!$K15,IF(AND(保険一覧!$J15="年払",MONTH(H$4)=保険一覧!$R15),保険一覧!$K15,0)),0) -> 0 | I16: =IF(OR(保険一覧!$S15="",I$4<保険一覧!$S15),IF(保険一覧!$J15="月払",保険一覧!$K15,IF(AND(保険一覧!$J15="年払",MONTH(I$4)=保険一覧!$R15),保険一覧!$K15,0)),0) -> 0 | J16: =IF(OR(保険一覧!$S15="",J$4<保険一覧!$S15),IF(保険一覧!$J15="月払",保険一覧!$K15,IF(AND(保険一覧!$J15="年払",MONTH(J$4)=保険一覧!$R15),保険一覧!$K15,0)),0) -> 0 | ... T16: =IF(OR(保険一覧!$S15="",T$4<保険一覧!$S15),IF(保険一覧!$J15="月払",保険一覧!$K15,IF(AND(保険一覧!$J15="年払",MONTH(T$4)=保険一覧!$R15),保険一覧!$K15,0)),0) -> 0 | U16: =SUM(C16:T16) -> 5698547 | V16: =SUMIFS(C16:T16,$C$4:$T$4,">="&DATE(2027,4,1),$C$4:$T$4,"<="&DATE(2028,3,1)) -> 5698547
A17: =保険一覧!A16&" "&保険一覧!B16&" "&保険一覧!H16 -> 12 大同生命 Ｔ 岡田 淳 | C17: =IF(OR(保険一覧!$S16="",C$4<保険一覧!$S16),IF(保険一覧!$J16="月払",保険一覧!$K16,IF(AND(保険一覧!$J16="年払",MONTH(C$4)=保険一覧!$R16),保険一覧!$K16,0)),0) -> 0 | D17: =IF(OR(保険一覧!$S16="",D$4<保険一覧!$S16),IF(保険一覧!$J16="月払",保険一覧!$K16,IF(AND(保険一覧!$J16="年払",MONTH(D$4)=保険一覧!$R16),保険一覧!$K16,0)),0) -> 0 | E17: =IF(OR(保険一覧!$S16="",E$4<保険一覧!$S16),IF(保険一覧!$J16="月払",保険一覧!$K16,IF(AND(保険一覧!$J16="年払",MONTH(E$4)=保険一覧!$R16),保険一覧!$K16,0)),0) -> 0 | F17: =IF(OR(保険一覧!$S16="",F$4<保険一覧!$S16),IF(保険一覧!$J16="月払",保険一覧!$K16,IF(AND(保険一覧!$J16="年払",MONTH(F$4)=保険一覧!$R16),保険一覧!$K16,0)),0) -> 0 | G17: =IF(OR(保険一覧!$S16="",G$4<保険一覧!$S16),IF(保険一覧!$J16="月払",保険一覧!$K16,IF(AND(保険一覧!$J16="年払",MONTH(G$4)=保険一覧!$R16),保険一覧!$K16,0)),0) -> 0 | H17: =IF(OR(保険一覧!$S16="",H$4<保険一覧!$S16),IF(保険一覧!$J16="月払",保険一覧!$K16,IF(AND(保険一覧!$J16="年払",MONTH(H$4)=保険一覧!$R16),保険一覧!$K16,0)),0) -> 0 | I17: =IF(OR(保険一覧!$S16="",I$4<保険一覧!$S16),IF(保険一覧!$J16="月払",保険一覧!$K16,IF(AND(保険一覧!$J16="年払",MONTH(I$4)=保険一覧!$R16),保険一覧!$K16,0)),0) -> 0 | J17: =IF(OR(保険一覧!$S16="",J$4<保険一覧!$S16),IF(保険一覧!$J16="月払",保険一覧!$K16,IF(AND(保険一覧!$J16="年払",MONTH(J$4)=保険一覧!$R16),保険一覧!$K16,0)),0) -> 0 | ... T17: =IF(OR(保険一覧!$S16="",T$4<保険一覧!$S16),IF(保険一覧!$J16="月払",保険一覧!$K16,IF(AND(保険一覧!$J16="年払",MONTH(T$4)=保険一覧!$R16),保険一覧!$K16,0)),0) -> 0 | U17: =SUM(C17:T17) -> 1707660 | V17: =SUMIFS(C17:T17,$C$4:$T$4,">="&DATE(2027,4,1),$C$4:$T$4,"<="&DATE(2028,3,1)) -> 1707660
... A25: =保険一覧!A24&" "&保険一覧!B24&" "&保険一覧!H24 -> 20 大同生命 坂本 麻莉 | C25: =IF(OR(保険一覧!$S24="",C$4<保険一覧!$S24),IF(保険一覧!$J24="月払",保険一覧!$K24,IF(AND(保険一覧!$J24="年払",MONTH(C$4)=保険一覧!$R24),保険一覧!$K24,0)),0) -> 28900 | D25: =IF(OR(保険一覧!$S24="",D$4<保険一覧!$S24),IF(保険一覧!$J24="月払",保険一覧!$K24,IF(AND(保険一覧!$J24="年払",MONTH(D$4)=保険一覧!$R24),保険一覧!$K24,0)),0) -> 28900 | E25: =IF(OR(保険一覧!$S24="",E$4<保険一覧!$S24),IF(保険一覧!$J24="月払",保険一覧!$K24,IF(AND(保険一覧!$J24="年払",MONTH(E$4)=保険一覧!$R24),保険一覧!$K24,0)),0) -> 28900 | F25: =IF(OR(保険一覧!$S24="",F$4<保険一覧!$S24),IF(保険一覧!$J24="月払",保険一覧!$K24,IF(AND(保険一覧!$J24="年払",MONTH(F$4)=保険一覧!$R24),保険一覧!$K24,0)),0) -> 28900 | G25: =IF(OR(保険一覧!$S24="",G$4<保険一覧!$S24),IF(保険一覧!$J24="月払",保険一覧!$K24,IF(AND(保険一覧!$J24="年払",MONTH(G$4)=保険一覧!$R24),保険一覧!$K24,0)),0) -> 28900 | H25: =IF(OR(保険一覧!$S24="",H$4<保険一覧!$S24),IF(保険一覧!$J24="月払",保険一覧!$K24,IF(AND(保険一覧!$J24="年払",MONTH(H$4)=保険一覧!$R24),保険一覧!$K24,0)),0) -> 28900 | I25: =IF(OR(保険一覧!$S24="",I$4<保険一覧!$S24),IF(保険一覧!$J24="月払",保険一覧!$K24,IF(AND(保険一覧!$J24="年払",MONTH(I$4)=保険一覧!$R24),保険一覧!$K24,0)),0) -> 28900 | J25: =IF(OR(保険一覧!$S24="",J$4<保険一覧!$S24),IF(保険一覧!$J24="月払",保険一覧!$K24,IF(AND(保険一覧!$J24="年払",MONTH(J$4)=保険一覧!$R24),保険一覧!$K24,0)),0) -> 28900 | ... T25: =IF(OR(保険一覧!$S24="",T$4<保険一覧!$S24),IF(保険一覧!$J24="月払",保険一覧!$K24,IF(AND(保険一覧!$J24="年払",MONTH(T$4)=保険一覧!$R24),保険一覧!$K24,0)),0) -> 28900 | U25: =SUM(C25:T25) -> 520200 | V25: =SUMIFS(C25:T25,$C$4:$T$4,">="&DATE(2027,4,1),$C$4:$T$4,"<="&DATE(2028,3,1)) -> 346800
A26: 保険料 現金支払計 | C26: =SUM(C6:C25) -> 892858 | D26: =SUM(D6:D25) -> 892858 | E26: =SUM(E6:E25) -> 892858 | F26: =SUM(F6:F25) -> 892858 | G26: =SUM(G6:G25) -> 892858 | H26: =SUM(H6:H25) -> 892858 | I26: =SUM(I6:I25) -> 892858 | J26: =SUM(J6:J25) -> 892858 | ... V26: =SUM(V6:V25) -> 33667055
A28: ※令和9年度計は暦の令和9年4月〜令和10年3月の合計。カレンダー範囲外の月は含まれません(初月は4行目の黄色でなく先頭セルの日付で変更可)。
